Workbook
Name CardAcimaDaMeta: #REF!
Name CardMediaProva: #REF!
Name CardQtdeNomes: #REF!
Name CardQtdeProvas: #REF!
Name FizeramProva: #REF!
Name NotaMedia: #REF!
Name tipoUsuarioLogado: "admin"
Name TotalMatriculas: #REF!

Sheet FOLHA_DP
A1: TIPO | B1: CONCAT RANKING PRODUÇÃO | C1: RANKING PRODUÇÃO | D1: CONCAT RANKING HORAS 70% SEMANA | E1: RANKING HORAS 70% SEMANA | F1: CONCAT RANKING HORAS 70% SÁBADO | G1: RANKING HORAS 70% SÁBADO | H1: CONCAT RANKING HORAS 100% | I1: Hora Extra 100% | J1: Nome da Empresa | K1: Nome do Funcionário | L1: Função | M1: Departamento | N1: Remuneração Líquida Folha | O1: Salário Base | P1: Admissão | Q1: Demissão | R1: Salário Base | S1: (Qtde): Salário Base | T1: Dias De Atestado | U1: (Qtde): Dias De Atestado | V1: Gratificação | W1: Adicional noturno 20% | X1: (Qtde): Adicional noturno 20% | Y1: Dev.desc.indevido | Z1: Salário Substituiçã | AA1: Reflexo S/ He Produção | AB1: Hora Extra 70% - Sabado | AC1: (Qtde): Hora Extra 70% - Sabado | AD1: Hora Extra 70% - Semana | AE1: (Qtde): Hora Extra 70% - Semana | AF1: Diferença de INSS Férias | AG1: Diferença INSS Férias (esocial) | AH1: Adicional H.e S/ Producao 70% | AI1: (Qtde): Adicional H.e S/ Producao 70% | AJ1: PRODUÇÃO | AK1: REFLEXO S PRODUÇÃO | AL1: Atrasos | AM1: (Qtde): Atrasos | AN1: Faltas em Dias | AO1: (Qtde): Faltas em Dias | AP1: Hora Extra 100% | AQ1: (Qtde): Hora Extra 100% | AR1: Repouso Remunerado | AS1: Adiantamento | AT1: Dsr sobre falta | AU1: (Qtde): Dsr sobre falta | AW1: PRODUÇÃO | AX1: HORAS 70% SEMANA | AY1: HORAS 70% SABADO | AZ1: HORAS 100%
A2: =VLOOKUP(L2,[1]VALIDAÇÃO!$D$13:$E$350,2,0) -> INDIRETO | B2: =C2&J2 -> 78RIO AVE 200 SPE LTDA. | C2: =1+SUMPRODUCT(($J$2:$J$1437=$J2)*(AW$2:AW$1437>AW2)) -> 78 | D2: =E2&J2 -> 8RIO AVE 200 SPE LTDA. | E2: =1+SUMPRODUCT(($J$2:$J$1437=$J2)*(AX$2:AX$1437>AX2)) -> 8 | F2: =G2&J2 -> 3RIO AVE 200 SPE LTDA. | G2: =1+SUMPRODUCT(($J$2:$J$1437=$J2)*(AY$2:AY$1437>AY2)) -> 3 | H2: =I2&J2 -> 78RIO AVE 200 SPE LTDA. | I2: =1+SUMPRODUCT(($J$2:$J$1437=$J2)*(AZ$2:AZ$1437>AZ2)) -> 78 | J2: RIO AVE 200 SPE LTDA. | K2: ABELARDO DOS SANTOS BARBOSA GOMES | L2: Encarregado de Armacao | M2: ADM | N2: 2553.77 | O2: 3434.3 | P2: 45937 | R2: 3434.3 | AB2: 291.54 | AC2: 1136.7143 | AD2: 385.72 | AE2: 1371.5714 | AR2: 152.54 | AS2: -1571.84 | AW2: =AJ2+ROW(C2)/1000000 -> 2e-06 | AX2: =AD2+ROW(C2)/1000000 -> 385.72 | AY2: =AB2+ROW(A2)/1000000 -> 291.54 | AZ2: =AP2+ROW(A2)/1000000 -> 2e-06
A3: =VLOOKUP(L3,[1]VALIDAÇÃO!$D$13:$E$350,2,0) -> DIRETO | B3: =C3&J3 -> 129RESERVA DO PAIVA SPE 03 LTDA | C3: =1+SUMPRODUCT(($J$2:$J$1437=J3)*($AW$2:$AW$1437>AW3)) -> 129 | D3: =E3&J3 -> 58RESERVA DO PAIVA SPE 03 LTDA | E3: =1+SUMPRODUCT(($J$2:$J$1437=$J3)*(AX$2:AX$1437>AX3)) -> 58 | F3: =G3&J3 -> 93RESERVA DO PAIVA SPE 03 LTDA | G3: =1+SUMPRODUCT(($J$2:$J$1437=$J3)*(AY$2:AY$1437>AY3)) -> 93 | H3: =I3&J3 -> 79RESERVA DO PAIVA SPE 03 LTDA | I3: =1+SUMPRODUCT(($J$2:$J$1437=$J3)*(AZ$2:AZ$1437>AZ3)) -> 79 | J3: RESERVA DO PAIVA SPE 03 LTDA | K3: ABIJOAN MIGUEL DA SILVA SOUZA | L3: Servente de Obras | M3: OBRA | N3: 836.19 | O3: 1332.47 | P3: 45798 | R3: 1332.47 | T3: 289.67 | U3: 5 | AA3: 0.18 | AB3: 63.27 | AC3: 590.95714 | AD3: 263.78 | AE3: 1546.27 | AH3: 0.76 | AI3: 0 | AJ3: 10.66 | AK3: 2.69 | AP3: 12.37 | AQ3: 98.2 | AR3: 73.77 | AS3: -695.2 | AW3: =AJ3+ROW(C3)/1000000 -> 10.660003 | AX3: =AD3+ROW(C3)/1000000 -> 263.78 | AY3: =AB3+ROW(A3)/1000000 -> 63.270003 | AZ3: =AP3+ROW(A3)/1000000 -> 12.370003
A4: =VLOOKUP(L4,[1]VALIDAÇÃO!$D$13:$E$350,2,0) -> DIRETO | B4: =C4&J4 -> 63RESERVA DO PAIVA SPE 03 LTDA | C4: =1+SUMPRODUCT(($J$2:$J$1437=J4)*($AW$2:$AW$1437>AW4)) -> 63 | D4: =E4&J4 -> 65RESERVA DO PAIVA SPE 03 LTDA | E4: =1+SUMPRODUCT(($J$2:$J$1437=$J4)*(AX$2:AX$1437>AX4)) -> 65 | F4: =G4&J4 -> 99RESERVA DO PAIVA SPE 03 LTDA | G4: =1+SUMPRODUCT(($J$2:$J$1437=$J4)*(AY$2:AY$1437>AY4)) -> 99 | H4: =I4&J4 -> 166RESERVA DO PAIVA SPE 03 LTDA | I4: =1+SUMPRODUCT(($J$2:$J$1437=$J4)*(AZ$2:AZ$1437>AZ4)) -> 166 | J4: RESERVA DO PAIVA SPE 03 LTDA | K4: ABRAAO JOSE GOMES | L4: Servente de Obras | M4: OBRA | N4: 1014.67 | O4: 1622.13 | P4: 45782 | R4: 1622.13 | W4: 0.63 | X4: 31.45 | AA4: 1.48 | AB4: 48.43 | AC4: 403.17143 | AD4: 251.35 | AE4: 1694.27 | AH4: 6.61 | AI4: 0 | AJ4: 212.85 | AK4: 46.43 | AL4: -2.39 | AM4: 18.17 | AR4: 67.69 | AS4: -695.2 | AW4: =AJ4+ROW(C4)/1000000 -> 212.85 | AX4: =AD4+ROW(C4)/1000000 -> 251.35 | AY4: =AB4+ROW(A4)/1000000 -> 48.430004 | AZ4: =AP4+ROW(A4)/1000000 -> 4e-06
A5: =VLOOKUP(L5,[1]VALIDAÇÃO!$D$13:$E$350,2,0) -> DIRETO | B5: =C5&J5 -> 20CONDOMINIO DO EDIFICIO EMPRESARIAL MARIE CURIE | C5: =1+SUMPRODUCT(($J$2:$J$1437=J5)*($AW$2:$AW$1437>AW5)) -> 20 | D5: =E5&J5 -> 64CONDOMINIO DO EDIFICIO EMPRESARIAL MARIE CURIE | E5: =1+SUMPRODUCT(($J$2:$J$1437=$J5)*(AX$2:AX$1437>AX5)) -> 64 | F5: =G5&J5 -> 51CONDOMINIO DO EDIFICIO EMPRESARIAL MARIE CURIE | G5: =1+SUMPRODUCT(($J$2:$J$1437=$J5)*(AY$2:AY$1437>AY5)) -> 51 | H5: =I5&J5 -> 129CONDOMINIO DO EDIFICIO EMPRESARIAL MARIE CURIE | I5: =1+SUMPRODUCT(($J$2:$J$1437=$J5)*(AZ$2:AZ$1437>AZ5)) -> 129 | J5: CONDOMINIO DO EDIFICIO EMPRESARIAL MARIE CURIE | K5: ABRAAO SOUZA DA SILVA | L5: Armador de Estrutura de Concreto | M5: CONDOMINIO MARIE OBRA | N5: 1276.29 | O5: 1617 | P5: 45362 | R5: 1617 | AA5: 2.54 | AB5: 69.72 | AC5: 234.35 | AD5: 111.96 | AE5: 376.32 | AH5: 12.34 | AI5: 0 | AJ5: 924.59 | AK5: 171.91 | AR5: 34.94 | AS5: -616 | AW5: =AJ5+ROW(C5)/1000000 -> 924.59001 | AX5: =AD5+ROW(C5)/1000000 -> 111.96 | AY5: =AB5+ROW(A5)/1000000 -> 69.720005 | AZ5: =AP5+ROW(A5)/1000000 -> 5e-06
A6: =VLOOKUP(L6,[1]VALIDAÇÃO!$D$13:$E$350,2,0) -> DIRETO | B6: =C6&J6 -> 39RIO AVE CARNEIROS 01 SPE LTDA. | C6: =1+SUMPRODUCT(($J$2:$J$1437=J6)*($AW$2:$AW$1437>AW6)) -> 39 | D6: =E6&J6 -> 90RIO AVE CARNEIROS 01 SPE LTDA. | E6: =1+SUMPRODUCT(($J$2:$J$1437=$J6)*(AX$2:AX$1437>AX6)) -> 90 | F6: =G6&J6 -> 10RIO AVE CARNEIROS 01 SPE LTDA. | G6: =1+SUMPRODUCT(($J$2:$J$1437=$J6)*(AY$2:AY$1437>AY6)) -> 10 | H6: =I6&J6 -> 49RIO AVE CARNEIROS 01 SPE LTDA. | I6: =1+SUMPRODUCT(($J$2:$J$1437=$J6)*(AZ$2:AZ$1437>AZ6)) -> 49 | J6: RIO AVE CARNEIROS 01 SPE LTDA. | K6: ABSOLON PAULO SILVA DE ARAUJO | L6: Pedreiro | M6: OBRA | N6: 1290.54 | O6: 2156 | P6: 45797 | R6: 2156 | AA6: 4.14 | AB6: 227.18 | AC6: 1112.1571 | AD6: 31.79 | AE6: 194.98571 | AH6: 18.71 | AI6: 0 | AJ6: 523.04 | AK6: 114.38 | AN6: -154 | AO6: 2 | AP6: 32.25 | AQ6: 192.65714 | AR6: 64.29 | AS6: -1014 | AT6: -154 | AU6: 2 | AW6: =AJ6+ROW(C6)/1000000 -> 523.04001 | AX6: =AD6+ROW(C6)/1000000 -> 31.790006 | AY6: =AB6+ROW(A6)/1000000 -> 227.18001 | AZ6: =AP6+ROW(A6)/1000000 -> 32.250006
A7: =VLOOKUP(L7,[1]VALIDAÇÃO!$D$13:$E$350,2,0) -> DIRETO | B7: =C7&J7 -> 43RIO AVE CARNEIROS 01 SPE LTDA. | C7: =1+SUMPRODUCT(($J$2:$J$1437=J7)*($AW$2:$AW$1437>AW7)) -> 43 | D7: =E7&J7 -> 72RIO AVE CARNEIROS 01 SPE LTDA. | E7: =1+SUMPRODUCT(($J$2:$J$1437=$J7)*(AX$2:AX$1437>AX7)) -> 72 | F7: =G7&J7 -> 12RIO AVE CARNEIROS 01 SPE LTDA. | G7: =1+SUMPRODUCT(($J$2:$J$1437=$J7)*(AY$2:AY$1437>AY7)) -> 12 | H7: =I7&J7 -> 13RIO AVE CARNEIROS 01 SPE LTDA. | I7: =1+SUMPRODUCT(($J$2:$J$1437=$J7)*(AZ$2:AZ$1437>AZ7)) -> 13 | J7: RIO AVE CARNEIROS 01 SPE LTDA. | K7: ADAILTON JOSE DA SILVA | L7: Servente de Obras | M7: OBRA | N7: 1107.91 | O7: 1622.13 | P7: 45782 | R7: 1622.13 | AA7: 5.52 | AB7: 218.19 | AC7: 1432.9857 | AD7: 66.92 | AE7: 545.01429 | AH7: 26.2 | AI7: 0 | AJ7: 489.02 | AK7: 107.54 | AP7: 70.46 | AQ7: 498.57143 | AR7: 74.92 | AS7: -695.2 | AW7: =AJ7+ROW(C7)/1000000 -> 489.02001 | AX7: =AD7+ROW(C7)/1000000 -> 66.920007 | AY7: =AB7+ROW(A7)/1000000 -> 218.19001 | AZ7: =AP7+ROW(A7)/1000000 -> 70.460007
A8: =VLOOKUP(L8,[1]VALIDAÇÃO!$D$13:$E$350,2,0) -> DIRETO | B8: =C8&J8 -> 67RESERVA DO PAIVA SPE 03 LTDA | C8: =1+SUMPRODUCT(($J$2:$J$1437=J8)*($AW$2:$AW$1437>AW8)) -> 67 | D8: =E8&J8 -> 124RESERVA DO PAIVA SPE 03 LTDA | E8: =1+SUMPRODUCT(($J$2:$J$1437=$J8)*(AX$2:AX$1437>AX8)) -> 124 | F8: =G8&J8 -> 166RESERVA DO PAIVA SPE 03 LTDA | G8: =1+SUMPRODUCT(($J$2:$J$1437=$J8)*(AY$2:AY$1437>AY8)) -> 166 | H8: =I8&J8 -> 165RESERVA DO PAIVA SPE 03 LTDA | I8: =1+SUMPRODUCT(($J$2:$J$1437=$J8)*(AZ$2:AZ$1437>AZ8)) -> 165 | J8: RESERVA DO PAIVA SPE 03 LTDA | K8: ADALBERTO ALVES DA SILVA | L8: Carpinteiro de Obras | M8: OBRA | N8: 1390.34 | O8: 2156 | P8: 45922 | R8: 2156 | AA8: 0.36 | AD8: 51.71 | AE8: 274.81429 | AH8: 1.54 | AI8: 0 | AJ8: 205.52 | AK8: 46.96 | AR8: 11.88 | AS8: -984 | AW8: =AJ8+ROW(C8)/1000000 -> 205.52001 | AX8: =AD8+ROW(C8)/1000000 -> 51.710008 | AY8: =AB8+ROW(A8)/1000000 -> 8e-06 | AZ8: =AP8+ROW(A8)/1000000 -> 8e-06
A9: =VLOOKUP(L9,[1]VALIDAÇÃO!$D$13:$E$350,2,0) -> DIRETO | B9: =C9&J9 -> 4RIO AVE 200 SPE LTDA. | C9: =1+SUMPRODUCT(($J$2:$J$1437=J9)*($AW$2:$AW$1437>AW9)) -> 4 | D9: =E9&J9 -> 22RIO AVE 200 SPE LTDA. | E9: =1+SUMPRODUCT(($J$2:$J$1437=$J9)*(AX$2:AX$1437>AX9)) -> 22 | F9: =G9&J9 -> 28RIO AVE 200 SPE LTDA. | G9: =1+SUMPRODUCT(($J$2:$J$1437=$J9)*(AY$2:AY$1437>AY9)) -> 28 | H9: =I9&J9 -> 18RIO AVE 200 SPE LTDA. | I9: =1+SUMPRODUCT(($J$2:$J$1437=$J9)*(AZ$2:AZ$1437>AZ9)) -> 18 | J9: RIO AVE 200 SPE LTDA. | K9: ADEILDO GOMES BARBOSA | L9: Carpinteiro de Obras | M9: OBRA | N9: 1942.57 | O9: 2156 | P9: 45938 | R9: 2156 | AA9: 7.81 | AB9: 40.56 | AC9: 556.42857 | AD9: 173.46 | AE9: 746.42857 | AH9: 32.11 | AI9: 0 | AJ9: 1152.05 | AK9: 259.33 | AP9: 10.6 | AQ9: 123.57143 | AR9: 54.51 | AS9: -924 | AW9: =AJ9+ROW(C9)/1000000 -> 1152.05 | AX9: =AD9+ROW(C9)/1000000 -> 173.46001 | AY9: =AB9+ROW(A9)/1000000 -> 40.560009 | AZ9: =AP9+ROW(A9)/1000000 -> 10.600009
A10: =VLOOKUP(L10,[1]VALIDAÇÃO!$D$13:$E$350,2,0) -> DIRETO | B10: =C10&J10 -> 65RESERVA DO PAIVA SPE 01 LTDA. | C10: =1+SUMPRODUCT(($J$2:$J$1437=J10)*($AW$2:$AW$1437>AW10)) -> 65 | D10: =E10&J10 -> 61RESERVA DO PAIVA SPE 01 LTDA. | E10: =1+SUMPRODUCT(($J$2:$J$1437=$J10)*(AX$2:AX$1437>AX10)) -> 61 | F10: =G10&J10 -> 59RESERVA DO PAIVA SPE 01 LTDA. | G10: =1+SUMPRODUCT(($J$2:$J$1437=$J10)*(AY$2:AY$1437>AY10)) -> 59 | H10: =I10&J10 -> 72RESERVA DO PAIVA SPE 01 LTDA. | I10: =1+SUMPRODUCT(($J$2:$J$1437=$J10)*(AZ$2:AZ$1437>AZ10)) -> 72 | J10: RESERVA DO PAIVA SPE 01 LTDA. | K10: ADEILDO MAXIMILIANO DA SILVA | L10: Servente de Obras | M10: OBRA | N10: 896.41 | O10: 1622.13 | P10: 45729 | R10: 1622.13 | AA10: 3.4 | AB10: 122.11 | AC10: 835.05714 | AD10: 81.12 | AE10: 440.54 | AH10: 13.49 | AI10: 0 | AJ10: 374.63 | AK10: 83.07 | AP10: 104.19 | AQ10: 605.6 | AR10: 77.78 | AS10: -695.2 | AW10: =AJ10+ROW(C10)/1000000 -> 374.63001 | AX10: =AD10+ROW(C10)/1000000 -> 81.12001 | AY10: =AB10+ROW(A10)/1000000 -> 122.11001 | AZ10: =AP10+ROW(A10)/1000000 -> 104.19001
A11: =VLOOKUP(L11,[1]VALIDAÇÃO!$D$13:$E$350,2,0) -> DIRETO | B11: =C11&J11 -> 90RESERVA DO PAIVA SPE 03 LTDA | C11: =1+SUMPRODUCT(($J$2:$J$1437=J11)*($AW$2:$AW$1437>AW11)) -> 90 | D11: =E11&J11 -> 41RESERVA DO PAIVA SPE 03 LTDA | E11: =1+SUMPRODUCT(($J$2:$J$1437=$J11)*(AX$2:AX$1437>AX11)) -> 41 | F11: =G11&J11 -> 38RESERVA DO PAIVA SPE 03 LTDA | G11: =1+SUMPRODUCT(($J$2:$J$1437=$J11)*(AY$2:AY$1437>AY11)) -> 38 | H11: =I11&J11 -> 12RESERVA DO PAIVA SPE 03 LTDA | I11: =1+SUMPRODUCT(($J$2:$J$1437=$J11)*(AZ$2:AZ$1437>AZ11)) -> 12 | J11: RESERVA DO PAIVA SPE 03 LTDA | K11: ADELMO BARROS DE ARAUJO | L11: Auxiliar de Eletricista | M11: OBRA | N11: 2123.43 | O11: 1622.13 | P11: 45978 | R11: 1622.13 | AA11: 8.51 | AB11: 244.87 | AC11: 1094 | AD11: 361.94 | AE11: 1617 | AH11: 39.14 | AI11: 0 | AJ11: 164.29 | AK11: 35.72 | AL11: -13.17 | AM11: 100 | AP11: 469 | AQ11: 1781 | AR11: 233.87 | AS11: -695.2 | AW11: =AJ11+ROW(C11)/1000000 -> 164.29001 | AX11: =AD11+ROW(C11)/1000000 -> 361.94001 | AY11: =AB11+ROW(A11)/1000000 -> 244.87001 | AZ11: =AP11+ROW(A11)/1000000 -> 469.00001
A12: =VLOOKUP(L12,[1]VALIDAÇÃO!$D$13:$E$350,2,0) -> DIRETO | B12: =C12&J12 -> 24RIO AVE CARNEIROS 01 SPE LTDA. | C12: =1+SUMPRODUCT(($J$2:$J$1437=J12)*($AW$2:$AW$1437>AW12)) -> 24 | D12: =E12&J12 -> 34RIO AVE CARNEIROS 01 SPE LTDA. | E12: =1+SUMPRODUCT(($J$2:$J$1437=$J12)*(AX$2:AX$1437>AX12)) -> 34 | F12: =G12&J12 -> 40RIO AVE CARNEIROS 01 SPE LTDA. | G12: =1+SUMPRODUCT(($J$2:$J$1437=$J12)*(AY$2:AY$1437>AY12)) -> 40 | H12: =I12&J12 -> 28RIO AVE CARNEIROS 01 SPE LTDA. | I12: =1+SUMPRODUCT(($J$2:$J$1437=$J12)*(AZ$2:AZ$1437>AZ12)) -> 28 | J12: RIO AVE CARNEIROS 01 SPE LTDA. | K12: ADIEL JOSE XAVIER DE LIMA | L12: Servente de Obras | M12: OBRA | N12: 1414.84 | O12: 1622.13 | P12: 45817 | R12: 1622.13 | AA12: 8.43 | AB12: 136 | AC12: 1270.2429 | AD12: 267.75 | AE12: 1796.2429 | AH12: 38.18 | AI12: 0 | AJ12: 631.75 | AK12: 137.8 | AP12: 43.33 | AQ12: 344.04286 | AR12: 98.35 | AS12: -765.2 | AW12: =AJ12+ROW(C12)/1000000 -> 631.75001 | AX12: =AD12+ROW(C12)/1000000 -> 267.75001 | AY12: =AB12+ROW(A12)/1000000 -> 136.00001 | AZ12: =AP12+ROW(A12)/1000000 -> 43.330012
A13: =VLOOKUP(L13,[1]VALIDAÇÃO!$D$13:$E$350,2,0) -> DIRETO | B13: =C13&J13 -> 25RIO AVE 200 SPE LTDA. | C13: =1+SUMPRODUCT(($J$2:$J$1437=J13)*($AW$2:$AW$1437>AW13)) -> 25 | D13: =E13&J13 -> 39RIO AVE 200 SPE LTDA. | E13: =1+SUMPRODUCT(($J$2:$J$1437=$J13)*(AX$2:AX$1437>AX13)) -> 39 | F13: =G13&J13 -> 39RIO AVE 200 SPE LTDA. | G13: =1+SUMPRODUCT(($J$2:$J$1437=$J13)*(AY$2:AY$1437>AY13)) -> 39 | H13: =I13&J13 -> 77RIO AVE 200 SPE LTDA. | I13: =1+SUMPRODUCT(($J$2:$J$1437=$J13)*(AZ$2:AZ$1437>AZ13)) -> 77 | J13: RIO AVE 200 SPE LTDA. | K13: ADIMARIO FLORENTINO PESSOA | L13: Armador de Estrutura de Concreto | M13: OBRA | N13: 1873.72 | O13: 2156 | P13: 45938 | R13: 2156 | AA13: 2.23 | AB13: 13.9 | AC13: 190.71429 | AD13: 108.51 | AE13: 508.71429 | AH13: 10.1 | AI13: 0 | AJ13: 656.02 | AK13: 150.22 | AR13: 26.63 | AS13: -998 | AW13: =AJ13+ROW(C13)/1000000 -> 656.02001 | AX13: =AD13+ROW(C13)/1000000 -> 108.51001 | AY13: =AB13+ROW(A13)/1000000 -> 13.900013 | AZ13: =AP13+ROW(A13)/1000000 -> 1.3e-05
A14: =VLOOKUP(L14,[1]VALIDAÇÃO!$D$13:$E$350,2,0) -> DIRETO | B14: =C14&J14 -> 12RESERVA DO PAIVA SPE 03 LTDA | C14: =1+SUMPRODUCT(($J$2:$J$1437=J14)*($AW$2:$AW$1437>AW14)) -> 12 | D14: =E14&J14 -> 74RESERVA DO PAIVA SPE 03 LTDA | E14: =1+SUMPRODUCT(($J$2:$J$1437=$J14)*(AX$2:AX$1437>AX14)) -> 74 | F14: =G14&J14 -> 8RESERVA DO PAIVA SPE 03 LTDA | G14: =1+SUMPRODUCT(($J$2:$J$1437=$J14)*(AY$2:AY$1437>AY14)) -> 8 | H14: =I14&J14 -> 3RESERVA DO PAIVA SPE 03 LTDA | I14: =1+SUMPRODUCT(($J$2:$J$1437=$J14)*(AZ$2:AZ$1437>AZ14)) -> 3 | J14: RESERVA DO PAIVA SPE 03 LTDA | K14: ADINALDO JOSE DA SILVA | L14: Pedreiro | M14: OBRA | N14: 2909.11 | O14: 2156 | P14: 45839 | R14: 2156 | AA14: 35.9 | AB14: 455.41 | AC14: 2267.6986 | AD14: 200.53 | AE14: 1571.5557 | AH14: 161.38 | AI14: 0 | AJ14: 955.35 | AK14: 209.34 | AL14: -2.13 | AM14: 12.17 | AP14: 976.2 | AQ14: 3969.8414 | AR14: 363.55 | AS14: -1014 | AW14: =AJ14+ROW(C14)/1000000 -> 955.35001 | AX14: =AD14+ROW(C14)/1000000 -> 200.53001 | AY14: =AB14+ROW(A14)/1000000 -> 455.41001 | AZ14: =AP14+ROW(A14)/1000000 -> 976.20001
A15: =VLOOKUP(L15,[1]VALIDAÇÃO!$D$13:$E$350,2,0) -> DIRETO | B15: =C15&J15 -> 88CONDOMINIO DO EDIFICIO EMPRESARIAL MARIE CURIE | C15: =1+SUMPRODUCT(($J$2:$J$1437=J15)*($AW$2:$AW$1437>AW15)) -> 88 | D15: =E15&J15 -> 112CONDOMINIO DO EDIFICIO EMPRESARIAL MARIE CURIE | E15: =1+SUMPRODUCT(($J$2:$J$1437=$J15)*(AX$2:AX$1437>AX15)) -> 112 | F15: =G15&J15 -> 90CONDOMINIO DO EDIFICIO EMPRESARIAL MARIE CURIE | G15: =1+SUMPRODUCT(($J$2:$J$1437=$J15)*(AY$2:AY$1437>AY15)) -> 90 | H15: =I15&J15 -> 128CONDOMINIO DO EDIFICIO EMPRESARIAL MARIE CURIE | I15: =1+SUMPRODUCT(($J$2:$J$1437=$J15)*(AZ$2:AZ$1437>AZ15)) -> 128 | J15: CONDOMINIO DO EDIFICIO EMPRESARIAL MARIE CURIE | K15: ADRIANO CARLOS DIAS | L15: Servente de Obras | M15: CONDOMINIO MARIE OBRA | N15: 731.72 | O15: 1622.13 | P15: 45579 | R15: 1622.13 | AA15: 0.04 | AB15: 8.02 | AC15: 45.711429 | AD15: 7.35 | AE15: 47.985714 | AH15: 0.29 | AI15: 0 | AJ15: 201.64 | AK15: 42.7 | AR15: 2.23 | AS15: -695.2 | AW15: =AJ15+ROW(C15)/1000000 -> 201.64001 | AX15: =AD15+ROW(C15)/1000000 -> 7.350015 | AY15: =AB15+ROW(A15)/1000000 -> 8.020015 | AZ15: =AP15+ROW(A15)/1000000 -> 1.5e-05
A16: =VLOOKUP(L16,[1]VALIDAÇÃO!$D$13:$E$350,2,0) -> DIRETO | B16: =C16&J16 -> 48CONDOMINIO DO EDIFICIO EMPRESARIAL MARIE CURIE | C16: =1+SUMPRODUCT(($J$2:$J$1437=J16)*($AW$2:$AW$1437>AW16)) -> 48 | D16: =E16&J16 -> 68CONDOMINIO DO EDIFICIO EMPRESARIAL MARIE CURIE | E16: =1+SUMPRODUCT(($J$2:$J$1437=$J16)*(AX$2:AX$1437>AX16)) -> 68 | F16: =G16&J16 -> 129CONDOMINIO DO EDIFICIO EMPRESARIAL MARIE CURIE | G16: =1+SUMPRODUCT(($J$2:$J$1437=$J16)*(AY$2:AY$1437>AY16)) -> 129 | H16: =I16&J16 -> 127CONDOMINIO DO EDIFICIO EMPRESARIAL MARIE CURIE | I16: =1+SUMPRODUCT(($J$2:$J$1437=$J16)*(AZ$2:AZ$1437>AZ16)) -> 127 | J16: CONDOMINIO DO EDIFICIO EMPRESARIAL MARIE CURIE | K16: ADRIANO CAVALCANTI MEDEIROS DE FRANÇA | L16: Servente de Obras | M16: CONDOMINIO MARIE OBRA | N16: 802.03 | O16: 1622.13 | P16: 45726 | R16: 1622.13 | AA16: 1.29 | AD16: 95.36 | AE16: 633.01429 | AH16: 6.6 | AI16: 0 | AJ16: 535.7 | AK16: 115.31 | AN16: -115.87 | AO16: 2 | AR16: 18.81 | AS16: -695.2 | AT16: -57.93 | AU16: 1 | AW16: =AJ16+ROW(C16)/1000000 -> 535.70002 | AX16: =AD16+ROW(C16)/1000000 -> 95.360016 | AY16: =AB16+ROW(A16)/1000000 -> 1.6e-05 | AZ16: =AP16+ROW(A16)/1000000 -> 1.6e-05
A17: =VLOOKUP(L17,[1]VALIDAÇÃO!$D$13:$E$350,2,0) -> DIRETO | B17: =C17&J17 -> 97RESERVA DO PAIVA SPE 03 LTDA | C17: =1+SUMPRODUCT(($J$2:$J$1437=J17)*($AW$2:$AW$1437>AW17)) -> 97 | D17: =E17&J17 -> 33RESERVA DO PAIVA SPE 03 LTDA | E17: =1+SUMPRODUCT(($J$2:$J$1437=$J17)*(AX$2:AX$1437>AX17)) -> 33 | F17: =G17&J17 -> 90RESERVA DO PAIVA SPE 03 LTDA | G17: =1+SUMPRODUCT(($J$2:$J$1437=$J17)*(AY$2:AY$1437>AY17)) -> 90 | H17: =I17&J17 -> 31RESERVA DO PAIVA SPE 03 LTDA | I17: =1+SUMPRODUCT(($J$2:$J$1437=$J17)*(AZ$2:AZ$1437>AZ17)) -> 31 | J17: RESERVA DO PAIVA SPE 03 LTDA | K17: ADRIANO DA ROCHA | L17: Servente de Obras | M17: OBRA | N17: 1275.24 | O17: 1622.13 | P17: 45873 | R17: 1622.13 | AA17: 3.86 | AB17: 81.44 | AC17: 1006.0714 | AD17: 429.34 | AE17: 3339.0714 | AH17: 16.44 | AI17: 0 | AJ17: 139.81 | AK17: 31.6 | AP17: 190.29 | AQ17: 940.78571 | AR17: 157.7 | AS17: -695.2 | AW17: =AJ17+ROW(C17)/1000000 -> 139.81002 | AX17: =AD17+ROW(C17)/1000000 -> 429.34002 | AY17: =AB17+ROW(A17)/1000000 -> 81.440017 | AZ17: =AP17+ROW(A17)/1000000 -> 190.29002
A18: =VLOOKUP(L18,[1]VALIDAÇÃO!$D$13:$E$350,2,0) -> DIRETO | B18: =C18&J18 -> 33RESERVA DO PAIVA SPE 03 LTDA | C18: =1+SUMPRODUCT(($J$2:$J$1437=J18)*($AW$2:$AW$1437>AW18)) -> 33 | D18: =E18&J18 -> 7RESERVA DO PAIVA SPE 03 LTDA | E18: =1+SUMPRODUCT(($J$2:$J$1437=$J18)*(AX$2:AX$1437>AX18)) -> 7 | F18: =G18&J18 -> 10RESERVA DO PAIVA SPE 03 LTDA | G18: =1+SUMPRODUCT(($J$2:$J$1437=$J18)*(AY$2:AY$1437>AY18)) -> 10 | H18: =I18&J18 -> 65RESERVA DO PAIVA SPE 03 LTDA | I18: =1+SUMPRODUCT(($J$2:$J$1437=$J18)*(AZ$2:AZ$1437>AZ18)) -> 65 | J18: RESERVA DO PAIVA SPE 03 LTDA | K18: ADRIANO DE SALES PEREIRA | L18: Servente de Obras | M18: OBRA | N18: 1750.08 | O18: 1622.13 | P18: 45488 | R18: 1622.13 | W18: 2.12 | X18: 73.88 | AA18: 15.83 | AB18: 430.27 | AC18: 2124.4071 | AD18: 1054.73 | AE18: 5243.3071 | AH18: 70.65 | AI18: 0 | AJ18: 408.94 | AK18: 90.23 | AL18: -7 | AM18: 53.17 | AP18: 34.65 | AQ18: 131.59 | AR18: 331.75 | AS18: -695.2 | AW18: =AJ18+ROW(C18)/1000000 -> 408.94002 | AX18: =AD18+ROW(C18)/1000000 -> 1054.73 | AY18: =AB18+ROW(A18)/1000000 -> 430.27002 | AZ18: =AP18+ROW(A18)/1000000 -> 34.650018
A19: =VLOOKUP(L19,[1]VALIDAÇÃO!$D$13:$E$350,2,0) -> DIRETO | B19: =C19&J19 -> 110RESERVA DO PAIVA SPE 03 LTDA | C19: =1+SUMPRODUCT(($J$2:$J$1437=J19)*($AW$2:$AW$1437>AW19)) -> 110 | D19: =E19&J19 -> 73RESERVA DO PAIVA SPE 03 LTDA | E19: =1+SUMPRODUCT(($J$2:$J$1437=$J19)*(AX$2:AX$1437>AX19)) -> 73 | F19: =G19&J19 -> 43RESERVA DO PAIVA SPE 03 LTDA | G19: =1+SUMPRODUCT(($J$2:$J$1437=$J19)*(AY$2:AY$1437>AY19)) -> 43 | H19: =I19&J19 -> 43RESERVA DO PAIVA SPE 03 LTDA | I19: =1+SUMPRODUCT(($J$2:$J$1437=$J19)*(AZ$2:AZ$1437>AZ19)) -> 43 | J19: RESERVA DO PAIVA SPE 03 LTDA | K19: ADRIANO FRANCISCO DOS SANTOS | L19: Servente de Obras | M19: OBRA | N19: 1371.07 | O19: 1622.13 | P19: 45938 | R19: 1622.13 | AA19: 2.24 | AB19: 218.91 | AC19: 978 | AD19: 205 | AE19: 1750.7143 | AH19: 10.01 | AI19: 0 | AJ19: 95.57 | AK19: 21.95 | AP19: 126.93 | AQ19: 482 | AR19: 124.43 | AS19: -695.2 | AW19: =AJ19+ROW(C19)/1000000 -> 95.570019 | AX19: =AD19+ROW(C19)/1000000 -> 205.00002 | AY19: =AB19+ROW(A19)/1000000 -> 218.91002 | AZ19: =AP19+ROW(A19)/1000000 -> 126.93002
A20: =VLOOKUP(L20,[1]VALIDAÇÃO!$D$13:$E$350,2,0) -> DIRETO | B20: =C20&J20 -> 12RIO AVE PRAIA HOTEL SPE LTDA. | C20: =1+SUMPRODUCT(($J$2:$J$1437=J20)*($AW$2:$AW$1437>AW20)) -> 12 | D20: =E20&J20 -> 8RIO AVE PRAIA HOTEL SPE LTDA. | E20: =1+SUMPRODUCT(($J$2:$J$1437=$J20)*(AX$2:AX$1437>AX20)) -> 8 | F20: =G20&J20 -> 17RIO AVE PRAIA HOTEL SPE LTDA. | G20: =1+SUMPRODUCT(($J$2:$J$1437=$J20)*(AY$2:AY$1437>AY20)) -> 17 | H20: =I20&J20 -> 21RIO AVE PRAIA HOTEL SPE LTDA. | I20: =1+SUMPRODUCT(($J$2:$J$1437=$J20)*(AZ$2:AZ$1437>AZ20)) -> 21 | J20: RIO AVE PRAIA HOTEL SPE LTDA. | K20: ADRIANO PEREIRA DE LIMA | L20: Servente de Obras | M20: Tomador | N20: 923.69 | O20: 1564.2 | P20: 45418 | R20: 1564.2 | AA20: 7.42 | AB20: 298.75 | AC20: 1544.21 | AD20: 384.03 | AE20: 1994.9414 | AH20: 34.13 | AI20: 0 | AJ20: 395.69 | AK20: 84.66 | AL20: -24.89 | AM20: 189 | AP20: 82.48 | AQ20: 327 | AR20: 160.37 | AS20: -695.2 | AW20: =AJ20+ROW(C20)/1000000 -> 395.69002 | AX20: =AD20+ROW(C20)/1000000 -> 384.03002 | AY20: =AB20+ROW(A20)/1000000 -> 298.75002 | AZ20: =AP20+ROW(A20)/1000000 -> 82.48002
A21: =VLOOKUP(L21,[1]VALIDAÇÃO!$D$13:$E$350,2,0) -> INDIRETO | B21: =C21&J21 -> 155RIO AVE CARNEIROS 01 SPE LTDA. | C21: =1+SUMPRODUCT(($J$2:$J$1437=J21)*($AW$2:$AW$1437>AW21)) -> 155 | D21: =E21&J21 -> 4RIO AVE CARNEIROS 01 SPE LTDA. | E21: =1+SUMPRODUCT(($J$2:$J$1437=$J21)*(AX$2:AX$1437>AX21)) -> 4 | F21: =G21&J21 -> 17RIO AVE CARNEIROS 01 SPE LTDA. | G21: =1+SUMPRODUCT(($J$2:$J$1437=$J21)*(AY$2:AY$1437>AY21)) -> 17 | H21: =I21&J21 -> 56RIO AVE CARNEIROS 01 SPE LTDA. | I21: =1+SUMPRODUCT(($J$2:$J$1437=$J21)*(AZ$2:AZ$1437>AZ21)) -> 56 | J21: RIO AVE CARNEIROS 01 SPE LTDA. | K21: ADRIANO QUEIROZ BEZERRA | L21: Encarregado de Obra | M21: GERAL | N21: 2852.15 | O21: 4121.16 | P21: 45761 | R21: 4121.16 | AB21: 197.82 | AC21: 584.64286 | AD21: 1192.72 | AE21: 2932.8571 | AL21: -121.09 | AM21: 362 | AP21: 26.52 | AQ21: 66.614286 | AR21: 289.95 | AS21: -1766.21 | AW21: =AJ21+ROW(C21)/1000000 -> 2.1e-05 | AX21: =AD21+ROW(C21)/1000000 -> 1192.72 | AY21: =AB21+ROW(A21)/1000000 -> 197.82002 | AZ21: =AP21+ROW(A21)/1000000 -> 26.520021
A22: =VLOOKUP(L22,[1]VALIDAÇÃO!$D$13:$E$350,2,0) -> DIRETO | B22: =C22&J22 -> 28CONDOMINIO DO EDIFICIO EMPRESARIAL MARIE CURIE | C22: =1+SUMPRODUCT(($J$2:$J$1437=J22)*($AW$2:$AW$1437>AW22)) -> 28 | D22: =E22&J22 -> 35CONDOMINIO DO EDIFICIO EMPRESARIAL MARIE CURIE | E22: =1+SUMPRODUCT(($J$2:$J$1437=$J22)*(AX$2:AX$1437>AX22)) -> 35 | F22: =G22&J22 -> 35CONDOMINIO DO EDIFICIO EMPRESARIAL MARIE CURIE | G22: =1+SUMPRODUCT(($J$2:$J$1437=$J22)*(AY$2:AY$1437>AY22)) -> 35 | H22: =I22&J22 -> 10CONDOMINIO DO EDIFICIO EMPRESARIAL MARIE CURIE | I22: =1+SUMPRODUCT(($J$2:$J$1437=$J22)*(AZ$2:AZ$1437>AZ22)) -> 10 | J22: CONDOMINIO DO EDIFICIO EMPRESARIAL MARIE CURIE | K22: ALAN LEANDRO GOMES | L22: Encanador | M22: CONDOMINIO MARIE OBRA | N22: 1583.33 | O22: 2156 | P22: 45691 | R22: 2156 | AA22: 7.88 | AB22: 128.12 | AC22: 605.15714 | AD22: 224.8 | AE22: 1005.7757 | AH22: 36.97 | AI22: 0 | AJ22: 755.66 | AK22: 163.77 | AP22: 177.28 | AQ22: 516.36143 | AR22: 113.17 | AS22: -924 | AW22: =AJ22+ROW(C22)/1000000 -> 755.66002 | AX22: =AD22+ROW(C22)/1000000 -> 224.80002 | AY22: =AB22+ROW(A22)/1000000 -> 128.12002 | AZ22: =AP22+ROW(A22)/1000000 -> 177.28002
A23: =VLOOKUP(L23,[1]VALIDAÇÃO!$D$13:$E$350,2,0) -> INDIRETO | B23: =C23&J23 -> 166RESERVA DO PAIVA SPE 03 LTDA | C23: =1+SUMPRODUCT(($J$2:$J$1437=J23)*($AW$2:$AW$1437>AW23)) -> 166 | D23: =E23&J23 -> 166RESERVA DO PAIVA SPE 03 LTDA | E23: =1+SUMPRODUCT(($J$2:$J$1437=$J23)*(AX$2:AX$1437>AX23)) -> 166 | F23: =G23&J23 -> 165RESERVA DO PAIVA SPE 03 LTDA | G23: =1+SUMPRODUCT(($J$2:$J$1437=$J23)*(AY$2:AY$1437>AY23)) -> 165 | H23: =I23&J23 -> 164RESERVA DO PAIVA SPE 03 LTDA | I23: =1+SUMPRODUCT(($J$2:$J$1437=$J23)*(AZ$2:AZ$1437>AZ23)) -> 164 | J23: RESERVA DO PAIVA SPE 03 LTDA | K23: ALBERT HASSLER SILVA DA MOTA | L23: Estagiario Engenharia Civil | M23: GERAL | N23: 1108.96 | P23: 45873 | AS23: -520 | AW23: =AJ23+ROW(C23)/1000000 -> 2.3e-05 | AX23: =AD23+ROW(C23)/1000000 -> 2.3e-05 | AY23: =AB23+ROW(A23)/1000000 -> 2.3e-05 | AZ23: =AP23+ROW(A23)/1000000 -> 2.3e-05
A24: =VLOOKUP(L24,[1]VALIDAÇÃO!$D$13:$E$350,2,0) -> DIRETO | B24: =C24&J24 -> 43RIO AVE 200 SPE LTDA. | C24: =1+SUMPRODUCT(($J$2:$J$1437=J24)*($AW$2:$AW$1437>AW24)) -> 43 | D24: =E24&J24 -> 4RIO AVE 200 SPE LTDA. | E24: =1+SUMPRODUCT(($J$2:$J$1437=$J24)*(AX$2:AX$1437>AX24)) -> 4 | F24: =G24&J24 -> 1RIO AVE 200 SPE LTDA. | G24: =1+SUMPRODUCT(($J$2:$J$1437=$J24)*(AY$2:AY$1437>AY24)) -> 1 | H24: =I24&J24 -> 1RIO AVE 200 SPE LTDA. | I24: =1+SUMPRODUCT(($J$2:$J$1437=$J24)*(AZ$2:AZ$1437>AZ24)) -> 1 | J24: RIO AVE 200 SPE LTDA. | K24: ALCIR JOSE ALVES DE OLIVEIRA | L24: Servente de Obras | M24: OBRA | N24: 1725.01 | O24: 1622.13 | P24: 45677 | R24: 1622.13 | AA24: 12.69 | AB24: 297.14 | AC24: 1667.2714 | AD24: 645.42 | AE24: 3614.9714 | AH24: 55.64 | AI24: 0 | AJ24: 323.21 | AK24: 71.65 | AP24: 517.28 | AQ24: 2167.9286 | AR24: 330.27 | AS24: -695.2 | AW24: =AJ24+ROW(C24)/1000000 -> 323.21002 | AX24: =AD24+ROW(C24)/1000000 -> 645.42002 | AY24: =AB24+ROW(A24)/1000000 -> 297.14002 | AZ24: =AP24+ROW(A24)/1000000 -> 517.28002
A25: =VLOOKUP(L25,[1]VALIDAÇÃO!$D$13:$E$350,2,0) -> DIRETO | B25: =C25&J25 -> 38RESERVA DO PAIVA SPE 01 LTDA. | C25: =1+SUMPRODUCT(($J$2:$J$1437=J25)*($AW$2:$AW$1437>AW25)) -> 38 | D25: =E25&J25 -> 72RESERVA DO PAIVA SPE 01 LTDA. | E25: =1+SUMPRODUCT(($J$2:$J$1437=$J25)*(AX$2:AX$1437>AX25)) -> 72 | F25: =G25&J25 -> 67RESERVA DO PAIVA SPE 01 LTDA. | G25: =1+SUMPRODUCT(($J$2:$J$1437=$J25)*(AY$2:AY$1437>AY25)) -> 67 | H25: =I25&J25 -> 41RESERVA DO PAIVA SPE 01 LTDA. | I25: =1+SUMPRODUCT(($J$2:$J$1437=$J25)*(AZ$2:AZ$1437>AZ25)) -> 41 | J25: RESERVA DO PAIVA SPE 01 LTDA. | K25: ALDECIR COSTA DO NASCIMENTO | L25: Pintor | M25: OBRA | N25: 1928.9 | O25: 2156 | P25: 45936 | R25: 2156 | AA25: 6.46 | AB25: 72.36 | AC25: 992.85714 | AD25: 42.49 | AE25: 509 | AH25: 27.08 | AI25: 0 | AJ25: 719.5 | AK25: 160.2 | AP25: 303.97 | AQ25: 1880.7143 | AR25: 107.75 | AS25: -924 | AW25: =AJ25+ROW(C25)/1000000 -> 719.50003 | AX25: =AD25+ROW(C25)/1000000 -> 42.490025 | AY25: =AB25+ROW(A25)/1000000 -> 72.360025 | AZ25: =AP25+ROW(A25)/1000000 -> 303.97003
A26: =VLOOKUP(L26,[1]VALIDAÇÃO!$D$13:$E$350,2,0) -> DIRETO | B26: =C26&J26 -> 12RIO AVE 200 SPE LTDA. | C26: =1+SUMPRODUCT(($J$2:$J$1437=J26)*($AW$2:$AW$1437>AW26)) -> 12 | D26: =E26&J26 -> 24RIO AVE 200 SPE LTDA. | E26: =1+SUMPRODUCT(($J$2:$J$1437=$J26)*(AX$2:AX$1437>AX26)) -> 24 | F26: =G26&J26 -> 23RIO AVE 200 SPE LTDA. | G26: =1+SUMPRODUCT(($J$2:$J$1437=$J26)*(AY$2:AY$1437>AY26)) -> 23 | H26: =I26&J26 -> 76RIO AVE 200 SPE LTDA. | I26: =1+SUMPRODUCT(($J$2:$J$1437=$J26)*(AZ$2:AZ$1437>AZ26)) -> 76 | J26: RIO AVE 200 SPE LTDA. | K26: ALDEMIR FLORENTINO PESSOA | L26: Armador de Estrutura de Concreto | M26: OBRA | N26: 2148.06 | O26: 2156 | P26: 45859 | R26: 2156 | AA26: 4.88 | AB26: 61.18 | AC26: 568.57143 | AD26: 150.6 | AE26: 808.42857 | AH26: 24.12 | AI26: 0 | AJ26: 986.48 | AK26: 214.82 | AR26: 42.23 | AS26: -1044 | AW26: =AJ26+ROW(C26)/1000000 -> 986.48003 | AX26: =AD26+ROW(C26)/1000000 -> 150.60003 | AY26: =AB26+ROW(A26)/1000000 -> 61.180026 | AZ26: =AP26+ROW(A26)/1000000 -> 2.6e-05
A27: =VLOOKUP(L27,[1]VALIDAÇÃO!$D$13:$E$350,2,0) -> DIRETO | B27: =C27&J27 -> 9RIO AVE PRAIA HOTEL SPE LTDA. | C27: =1+SUMPRODUCT(($J$2:$J$1437=J27)*($AW$2:$AW$1437>AW27)) -> 9 | D27: =E27&J27 -> 12RIO AVE PRAIA HOTEL SPE LTDA. | E27: =1+SUMPRODUCT(($J$2:$J$1437=$J27)*(AX$2:AX$1437>AX27)) -> 12 | F27: =G27&J27 -> 19RIO AVE PRAIA HOTEL SPE LTDA. | G27: =1+SUMPRODUCT(($J$2:$J$1437=$J27)*(AY$2:AY$1437>AY27)) -> 19 | H27: =I27&J27 -> 18RIO AVE PRAIA HOTEL SPE LTDA. | I27: =1+SUMPRODUCT(($J$2:$J$1437=$J27)*(AZ$2:AZ$1437>AZ27)) -> 18 | J27: RIO AVE PRAIA HOTEL SPE LTDA. | K27: ALECSANDRO FRANCISCO ALVES | L27: Servente de Obras | M27: Tomador | N27: 1355.35 | O27: 1564.2 | P27: 45579 | R27: 1564.2 | AA27: 7.44 | AB27: 277.17 | AC27: 1331.3929 | AD27: 184.92 | AE27: 900.14143 | AH27: 33.47 | AI27: 0 | AJ27: 458.53 | AK27: 97.7 | AL27: -8.56 | AM27: 65 | AP27: 198.75 | AQ27: 831.68 | AR27: 147.79 | AS27: -695.2 | AW27: =AJ27+ROW(C27)/1000000 -> 458.53003 | AX27: =AD27+ROW(C27)/1000000 -> 184.92003 | AY27: =AB27+ROW(A27)/1000000 -> 277.17003 | AZ27: =AP27+ROW(A27)/1000000 -> 198.75003
A28: =VLOOKUP(L28,[1]VALIDAÇÃO!$D$13:$E$350,2,0) -> INDIRETO | B28: =C28&J28 -> 129CONDOMINIO DO EDIFICIO EMPRESARIAL MARIE CURIE | C28: =1+SUMPRODUCT(($J$2:$J$1437=J28)*($AW$2:$AW$1437>AW28)) -> 129 | D28: =E28&J28 -> 52CONDOMINIO DO EDIFICIO EMPRESARIAL MARIE CURIE | E28: =1+SUMPRODUCT(($J$2:$J$1437=$J28)*(AX$2:AX$1437>AX28)) -> 52 | F28: =G28&J28 -> 13CONDOMINIO DO EDIFICIO EMPRESARIAL MARIE CURIE | G28: =1+SUMPRODUCT(($J$2:$J$1437=$J28)*(AY$2:AY$1437>AY28)) -> 13 | H28: =I28&J28 -> 4CONDOMINIO DO EDIFICIO EMPRESARIAL MARIE CURIE | I28: =1+SUMPRODUCT(($J$2:$J$1437=$J28)*(AZ$2:AZ$1437>AZ28)) -> 4 | J28: CONDOMINIO DO EDIFICIO EMPRESARIAL MARIE CURIE | K28: ALEX ALBUQUERQUE DE MELO | L28: ENCARREGADO ELETRICISTA | M28: CONDOMINIO MARIE OBRA | N28: 1788.2 | O28: 2747.44 | P28: 45918 | R28: 2747.44 | AB28: 286.61 | AC28: 756 | AD28: 152.82 | AE28: 646.85714 | AP28: 328.51 | AQ28: 907.67143 | AR28: 169.56 | AS28: -1177.48 | AW28: =AJ28+ROW(C28)/1000000 -> 2.8e-05 | AX28: =AD28+ROW(C28)/1000000 -> 152.82003 | AY28: =AB28+ROW(A28)/1000000 -> 286.61003 | AZ28: =AP28+ROW(A28)/1000000 -> 328.51003
A29: =VLOOKUP(L29,[1]VALIDAÇÃO!$D$13:$E$350,2,0) -> DIRETO | B29: =C29&J29 -> 83CONDOMINIO DO EDIFICIO EMPRESARIAL MARIE CURIE | C29: =1+SUMPRODUCT(($J$2:$J$1437=J29)*($AW$2:$AW$1437>AW29)) -> 83 | D29: =E29&J29 -> 74CONDOMINIO DO EDIFICIO EMPRESARIAL MARIE CURIE | E29: =1+SUMPRODUCT(($J$2:$J$1437=$J29)*(AX$2:AX$1437>AX29)) -> 74 | F29: =G29&J29 -> 43CONDOMINIO DO EDIFICIO EMPRESARIAL MARIE CURIE | G29: =1+SUMPRODUCT(($J$2:$J$1437=$J29)*(AY$2:AY$1437>AY29)) -> 43 | H29: =I29&J29 -> 126CONDOMINIO DO EDIFICIO EMPRESARIAL MARIE CURIE | I29: =1+SUMPRODUCT(($J$2:$J$1437=$J29)*(AZ$2:AZ$1437>AZ29)) -> 126 | J29: CONDOMINIO DO EDIFICIO EMPRESARIAL MARIE CURIE | K29: ALEX FAUSTINO DA SILVA | L29: Servente de Obras | M29: CONDOMINIO MARIE OBRA | N29: 720.9 | O29: 1622.13 | P29: 45579 | R29: 1622.13 | AA29: 0.96 | AB29: 95.89 | AC29: 554.21286 | AD29: 78.73 | AE29: 456.87857 | AH29: 4.47 | AI29: 0 | AJ29: 220.09 | AK29: 46.61 | AL29: -2.53 | AM29: 19.19 | AN29: -57.93 | AO29: 1 | AR29: 36.33 | AS29: -695.2 | AT29: -57.93 | AU29: 1 | AW29: =AJ29+ROW(C29)/1000000 -> 220.09003 | AX29: =AD29+ROW(C29)/1000000 -> 78.730029 | AY29: =AB29+ROW(A29)/1000000 -> 95.890029 | AZ29: =AP29+ROW(A29)/1000000 -> 2.9e-05
A30: =VLOOKUP(L30,[1]VALIDAÇÃO!$D$13:$E$350,2,0) -> DIRETO | B30: =C30&J30 -> 30RESERVA DO PAIVA SPE 01 LTDA. | C30: =1+SUMPRODUCT(($J$2:$J$1437=J30)*($AW$2:$AW$1437>AW30)) -> 30 | D30: =E30&J30 -> 11RESERVA DO PAIVA SPE 01 LTDA. | E30: =1+SUMPRODUCT(($J$2:$J$1437=$J30)*(AX$2:AX$1437>AX30)) -> 11 | F30: =G30&J30 -> 20RESERVA DO PAIVA SPE 01 LTDA. | G30: =1+SUMPRODUCT(($J$2:$J$1437=$J30)*(AY$2:AY$1437>AY30)) -> 20 | H30: =I30&J30 -> 10RESERVA DO PAIVA SPE 01 LTDA. | I30: =1+SUMPRODUCT(($J$2:$J$1437=$J30)*(AZ$2:AZ$1437>AZ30)) -> 10 | J30: RESERVA DO PAIVA SPE 01 LTDA. | K30: ALEX FERREIRA DA SILVA | L30: Auxiliar de Eletricista | M30: OBRA | N30: 2844.89 | O30: 1622.13 | P30: 45587 | R30: 1622.13 | AA30: 44.07 | AB30: 421.02 | AC30: 2147.8971 | AD30: 887.96 | AE30: 4443.9786 | AH30: 199.93 | AI30: 0 | AJ30: 781.07 | AK30: 170.7 | AP30: 802.96 | AQ30: 3276.5971 | AR30: 466.83 | AS30: -695.2 | AW30: =AJ30+ROW(C30)/1000000 -> 781.07003 | AX30: =AD30+ROW(C30)/1000000 -> 887.96003 | AY30: =AB30+ROW(A30)/1000000 -> 421.02003 | AZ30: =AP30+ROW(A30)/1000000 -> 802.96003
A31: =VLOOKUP(L31,[1]VALIDAÇÃO!$D$13:$E$350,2,0) -> DIRETO | B31: =C31&J31 -> 8RIO AVE PRAIA HOTEL SPE LTDA. | C31: =1+SUMPRODUCT(($J$2:$J$1437=J31)*($AW$2:$AW$1437>AW31)) -> 8 | D31: =E31&J31 -> 9RIO AVE PRAIA HOTEL SPE LTDA. | E31: =1+SUMPRODUCT(($J$2:$J$1437=$J31)*(AX$2:AX$1437>AX31)) -> 9 | F31: =G31&J31 -> 15RIO AVE PRAIA HOTEL SPE LTDA. | G31: =1+SUMPRODUCT(($J$2:$J$1437=$J31)*(AY$2:AY$1437>AY31)) -> 15 | H31: =I31&J31 -> 6RIO AVE PRAIA HOTEL SPE LTDA. | I31: =1+SUMPRODUCT(($J$2:$J$1437=$J31)*(AZ$2:AZ$1437>AZ31)) -> 6 | J31: RIO AVE PRAIA HOTEL SPE LTDA. | K31: ALEXANDRE BARBOSA DE MELO | L31: Servente de Obras | M31: Tomador | N31: 1781.14 | O31: 1564.2 | P31: 45328 | R31: 1564.2 | AA31: 15.27 | AB31: 307.06 | AC31: 1602.6986 | AD31: 371.31 | AE31: 1732.4071 | AH31: 69.85 | AI31: 0 | AJ31: 490.7 | AK31: 105.09 | AP31: 622.84 | AQ31: 2405.0543 | AR31: 276.14 | AS31: -695.2 | AW31: =AJ31+ROW(C31)/1000000 -> 490.70003 | AX31: =AD31+ROW(C31)/1000000 -> 371.31003 | AY31: =AB31+ROW(A31)/1000000 -> 307.06003 | AZ31: =AP31+ROW(A31)/1000000 -> 622.84003
A32: =VLOOKUP(L32,[1]VALIDAÇÃO!$D$13:$E$350,2,0) -> DIRETO | B32: =C32&J32 -> 74CONDOMINIO DO EDIFICIO EMPRESARIAL MARIE CURIE | C32: =1+SUMPRODUCT(($J$2:$J$1437=J32)*($AW$2:$AW$1437>AW32)) -> 74 | D32: =E32&J32 -> 25CONDOMINIO DO EDIFICIO EMPRESARIAL MARIE CURIE | E32: =1+SUMPRODUCT(($J$2:$J$1437=$J32)*(AX$2:AX$1437>AX32)) -> 25 | F32: =G32&J32 -> 8CONDOMINIO DO EDIFICIO EMPRESARIAL MARIE CURIE | G32: =1+SUMPRODUCT(($J$2:$J$1437=$J32)*(AY$2:AY$1437>AY32)) -> 8 | H32: =I32&J32 -> 125CONDOMINIO DO EDIFICIO EMPRESARIAL MARIE CURIE | I32: =1+SUMPRODUCT(($J$2:$J$1437=$J32)*(AZ$2:AZ$1437>AZ32)) -> 125 | J32: CONDOMINIO DO EDIFICIO EMPRESARIAL MARIE CURIE | K32: ALEXANDRE BIBIANO ALVES | L32: Operador de betoneira | M32: CONDOMINIO MARIE OBRA | N32: 1434.28 | O32: 2156 | P32: 45446 | R32: 2156 | AA32: 3.68 | AB32: 328.29 | AC32: 1156.2757 | AD32: 276.87 | AE32: 960.61571 | AH32: 17.43 | AI32: 0 | AJ32: 284.56 | AK32: 60.76 | AR32: 125.04 | AS32: -924 | AW32: =AJ32+ROW(C32)/1000000 -> 284.56003 | AX32: =AD32+ROW(C32)/1000000 -> 276.87003 | AY32: =AB32+ROW(A32)/1000000 -> 328.29003 | AZ32: =AP32+ROW(A32)/1000000 -> 3.2e-05
A33: =VLOOKUP(L33,[1]VALIDAÇÃO!$D$13:$E$350,2,0) -> DIRETO | B33: =C33&J33 -> 8RIO AVE 130 SPE LTDA | C33: =1+SUMPRODUCT(($J$2:$J$1437=J33)*($AW$2:$AW$1437>AW33)) -> 8 | D33: =E33&J33 -> 27RIO AVE 130 SPE LTDA | E33: =1+SUMPRODUCT(($J$2:$J$1437=$J33)*(AX$2:AX$1437>AX33)) -> 27 | F33: =G33&J33 -> 45RIO AVE 130 SPE LTDA | G33: =1+SUMPRODUCT(($J$2:$J$1437=$J33)*(AY$2:AY$1437>AY33)) -> 45 | H33: =I33&J33 -> 24RIO AVE 130 SPE LTDA | I33: =1+SUMPRODUCT(($J$2:$J$1437=$J33)*(AZ$2:AZ$1437>AZ33)) -> 24 | J33: RIO AVE 130 SPE LTDA | K33: ALEXANDRE JOSE DOS SANTOS | L33: Encanador | M33: OBRA | N33: 1860.77 | O33: 2156 | P33: 45726 | R33: 2156 | AA33: 11.25 | AB33: 60.75 | AC33: 312.54286 | AD33: 299.49 | AE33: 1160.9143 | AH33: 51.68 | AI33: 0 | AJ33: 1108.37 | AK33: 239.63 | AL33: -11.2 | AM33: 64 | AP33: 109.55 | AQ33: 313 | AR33: 101.91 | AS33: -924 | AW33: =AJ33+ROW(C33)/1000000 -> 1108.37 | AX33: =AD33+ROW(C33)/1000000 -> 299.49003 | AY33: =AB33+ROW(A33)/1000000 -> 60.750033 | AZ33: =AP33+ROW(A33)/1000000 -> 109.55003
A34: =VLOOKUP(L34,[1]VALIDAÇÃO!$D$13:$E$350,2,0) -> DIRETO | B34: =C34&J34 -> 116RESERVA DO PAIVA SPE 03 LTDA | C34: =1+SUMPRODUCT(($J$2:$J$1437=J34)*($AW$2:$AW$1437>AW34)) -> 116 | D34: =E34&J34 -> 165RESERVA DO PAIVA SPE 03 LTDA | E34: =1+SUMPRODUCT(($J$2:$J$1437=$J34)*(AX$2:AX$1437>AX34)) -> 165 | F34: =G34&J34 -> 73RESERVA DO PAIVA SPE 03 LTDA | G34: =1+SUMPRODUCT(($J$2:$J$1437=$J34)*(AY$2:AY$1437>AY34)) -> 73 | H34: =I34&J34 -> 163RESERVA DO PAIVA SPE 03 LTDA | I34: =1+SUMPRODUCT(($J$2:$J$1437=$J34)*(AZ$2:AZ$1437>AZ34)) -> 163 | J34: RESERVA DO PAIVA SPE 03 LTDA | K34: ALEXANDRE MAGNO CAVALCANTE | L34: Servente de Obras | M34: OBRA | N34: 930.17 | O34: 1622.13 | P34: 45964 | R34: 1622.13 | AA34: 0.46 | AB34: 108.34 | AC34: 484 | AH34: 2.11 | AI34: 0 | AJ34: 82.14 | AK34: 17.86 | AR34: 23.55 | AS34: -695.2 | AW34: =AJ34+ROW(C34)/1000000 -> 82.140034 | AX34: =AD34+ROW(C34)/1000000 -> 3.4e-05 | AY34: =AB34+ROW(A34)/1000000 -> 108.34003 | AZ34: =AP34+ROW(A34)/1000000 -> 3.4e-05
A35: =VLOOKUP(L35,[1]VALIDAÇÃO!$D$13:$E$350,2,0) -> DIRETO | B35: =C35&J35 -> 154RIO AVE CARNEIROS 01 SPE LTDA. | C35: =1+SUMPRODUCT(($J$2:$J$1437=J35)*($AW$2:$AW$1437>AW35)) -> 154 | D35: =E35&J35 -> 118RIO AVE CARNEIROS 01 SPE LTDA. | E35: =1+SUMPRODUCT(($J$2:$J$1437=$J35)*(AX$2:AX$1437>AX35)) -> 118 | F35: =G35&J35 -> 155RIO AVE CARNEIROS 01 SPE LTDA. | G35: =1+SUMPRODUCT(($J$2:$J$1437=$J35)*(AY$2:AY$1437>AY35)) -> 155 | H35: =I35&J35 -> 155RIO AVE CARNEIROS 01 SPE LTDA. | I35: =1+SUMPRODUCT(($J$2:$J$1437=$J35)*(AZ$2:AZ$1437>AZ35)) -> 155 | J35: RIO AVE CARNEIROS 01 SPE LTDA. | K35: ALEXANDRE VICENTE DE ARAUJO | L35: Servente de Obras | M35: OBRA | N35: 661.91 | O35: 1506.27 | P35: 45994 | R35: 1506.27 | AD35: 6.27 | AE35: 28 | AR35: 1.49 | AS35: -735.2 | AW35: =AJ35+ROW(C35)/1000000 -> 3.5e-05 | AX35: =AD35+ROW(C35)/1000000 -> 6.270035 | AY35: =AB35+ROW(A35)/1000000 -> 3.5e-05 | AZ35: =AP35+ROW(A35)/1000000 -> 3.5e-05
A36: =VLOOKUP(L36,[1]VALIDAÇÃO!$D$13:$E$350,2,0) -> INDIRETO | B36: =C36&J36 -> 128CONDOMINIO DO EDIFICIO EMPRESARIAL MARIE CURIE | C36: =1+SUMPRODUCT(($J$2:$J$1437=J36)*($AW$2:$AW$1437>AW36)) -> 128 | D36: =E36&J36 -> 4CONDOMINIO DO EDIFICIO EMPRESARIAL MARIE CURIE | E36: =1+SUMPRODUCT(($J$2:$J$1437=$J36)*(AX$2:AX$1437>AX36)) -> 4 | F36: =G36&J36 -> 29CONDOMINIO DO EDIFICIO EMPRESARIAL MARIE CURIE | G36: =1+SUMPRODUCT(($J$2:$J$1437=$J36)*(AY$2:AY$1437>AY36)) -> 29 | H36: =I36&J36 -> 124CONDOMINIO DO EDIFICIO EMPRESARIAL MARIE CURIE | I36: =1+SUMPRODUCT(($J$2:$J$1437=$J36)*(AZ$2:AZ$1437>AZ36)) -> 124 | J36: CONDOMINIO DO EDIFICIO EMPRESARIAL MARIE CURIE | K36: ALEXSANDRO FAUSTINO SOARES | L36: Encarregado de Obra | M36: CONDOMINIO MARIE OBRA | N36: 1380.93 | O36: 3777.73 | P36: 45603 | R36: 3777.73 | AB36: 143.4 | AC36: 306.58714 | AD36: 740.08 | AE36: 1717.7671 | AR36: 177.21 | AS36: -1619.03 | AW36: =AJ36+ROW(C36)/1000000 -> 3.6e-05 | AX36: =AD36+ROW(C36)/1000000 -> 740.08004 | AY36: =AB36+ROW(A36)/1000000 -> 143.40004 | AZ36: =AP36+ROW(A36)/1000000 -> 3.6e-05
A37: =VLOOKUP(L37,[1]VALIDAÇÃO!$D$13:$E$350,2,0) -> INDIRETO | B37: =C37&J37 -> 127CONDOMINIO DO EDIFICIO EMPRESARIAL MARIE CURIE | C37: =1+SUMPRODUCT(($J$2:$J$1437=J37)*($AW$2:$AW$1437>AW37)) -> 127 | D37: =E37&J37 -> 77CONDOMINIO DO EDIFICIO EMPRESARIAL MARIE CURIE | E37: =1+SUMPRODUCT(($J$2:$J$1437=$J37)*(AX$2:AX$1437>AX37)) -> 77 | F37: =G37&J37 -> 128CONDOMINIO DO EDIFICIO EMPRESARIAL MARIE CURIE | G37: =1+SUMPRODUCT(($J$2:$J$1437=$J37)*(AY$2:AY$1437>AY37)) -> 128 | H37: =I37&J37 -> 123CONDOMINIO DO EDIFICIO EMPRESARIAL MARIE CURIE | I37: =1+SUMPRODUCT(($J$2:$J$1437=$J37)*(AZ$2:AZ$1437>AZ37)) -> 123 | J37: CONDOMINIO DO EDIFICIO EMPRESARIAL MARIE CURIE | K37: ALICE VITORIA INACIO VENANCIO | L37: Assistente de DP | M37: CONDOMINIO MARIE OBRA | N37: 817.39 | O37: 2156 | P37: 45670 | R37: 2156 | AD37: 73.13 | AE37: 266.30429 | AR37: 15.57 | AS37: -924 | AW37: =AJ37+ROW(C37)/1000000 -> 3.7e-05 | AX37: =AD37+ROW(C37)/1000000 -> 73.130037 | AY37: =AB37+ROW(A37)/1000000 -> 3.7e-05 | AZ37: =AP37+ROW(A37)/1000000 -> 3.7e-05
A38: =VLOOKUP(L38,[1]VALIDAÇÃO!$D$13:$E$350,2,0) -> DIRETO | B38: =C38&J38 -> 101CONDOMINIO DO EDIFICIO EMPRESARIAL MARIE CURIE | C38: =1+SUMPRODUCT(($J$2:$J$1437=J38)*($AW$2:$AW$1437>AW38)) -> 101 | D38: =E38&J38 -> 40CONDOMINIO DO EDIFICIO EMPRESARIAL MARIE CURIE | E38: =1+SUMPRODUCT(($J$2:$J$1437=$J38)*(AX$2:AX$1437>AX38)) -> 40 | F38: =G38&J38 -> 127CONDOMINIO DO EDIFICIO EMPRESARIAL MARIE CURIE | G38: =1+SUMPRODUCT(($J$2:$J$1437=$J38)*(AY$2:AY$1437>AY38)) -> 127 | H38: =I38&J38 -> 122CONDOMINIO DO EDIFICIO EMPRESARIAL MARIE CURIE | I38: =1+SUMPRODUCT(($J$2:$J$1437=$J38)*(AZ$2:AZ$1437>AZ38)) -> 122 | J38: CONDOMINIO DO EDIFICIO EMPRESARIAL MARIE CURIE | K38: ALINDOALDO ALVES DA SILVA | L38: Encanador | M38: CONDOMINIO MARIE OBRA | N38: 1221.87 | O38: 2156 | P38: 45992 | R38: 2156 | AA38: 1.28 | AD38: 194.62 | AE38: 654.19 | AH38: 5.87 | AI38: 0 | AJ38: 169.23 | AK38: 36.79 | AR38: 42.31 | AS38: -924 | AW38: =AJ38+ROW(C38)/1000000 -> 169.23004 | AX38: =AD38+ROW(C38)/1000000 -> 194.62004 | AY38: =AB38+ROW(A38)/1000000 -> 3.8e-05 | AZ38: =AP38+ROW(A38)/1000000 -> 3.8e-05
A39: =VLOOKUP(L39,[1]VALIDAÇÃO!$D$13:$E$350,2,0) -> DIRETO | B39: =C39&J39 -> 52RESERVA DO PAIVA SPE 03 LTDA | C39: =1+SUMPRODUCT(($J$2:$J$1437=J39)*($AW$2:$AW$1437>AW39)) -> 52 | D39: =E39&J39 -> 39RESERVA DO PAIVA SPE 03 LTDA | E39: =1+SUMPRODUCT(($J$2:$J$1437=$J39)*(AX$2:AX$1437>AX39)) -> 39 | F39: =G39&J39 -> 106RESERVA DO PAIVA SPE 03 LTDA | G39: =1+SUMPRODUCT(($J$2:$J$1437=$J39)*(AY$2:AY$1437>AY39)) -> 106 | H39: =I39&J39 -> 162RESERVA DO PAIVA SPE 03 LTDA | I39: =1+SUMPRODUCT(($J$2:$J$1437=$J39)*(AZ$2:AZ$1437>AZ39)) -> 162 | J39: RESERVA DO PAIVA SPE 03 LTDA | K39: ALISSON DA SILVA VIEIRA | L39: Servente de Obras | M39: OBRA | N39: 361.65 | O39: 1622.13 | P39: 45509 | R39: 1622.13 | W39: 1.82 | X39: 63.43 | AA39: 2.89 | AB39: 37.63 | AC39: 212.71714 | AD39: 375.38 | AE39: 2105.2086 | AH39: 13.26 | AI39: 0 | AJ39: 285.26 | AK39: 62.2 | AL39: -24.49 | AM39: 186 | AR39: 88.56 | AS39: -695.2 | AW39: =AJ39+ROW(C39)/1000000 -> 285.26004 | AX39: =AD39+ROW(C39)/1000000 -> 375.38004 | AY39: =AB39+ROW(A39)/1000000 -> 37.630039 | AZ39: =AP39+ROW(A39)/1000000 -> 3.9e-05
A40: =VLOOKUP(L40,[1]VALIDAÇÃO!$D$13:$E$350,2,0) -> DIRETO | B40: =C40&J40 -> 26RIO AVE 200 SPE LTDA. | C40: =1+SUMPRODUCT(($J$2:$J$1437=J40)*($AW$2:$AW$1437>AW40)) -> 26 | D40: =E40&J40 -> 27RIO AVE 200 SPE LTDA. | E40: =1+SUMPRODUCT(($J$2:$J$1437=$J40)*(AX$2:AX$1437>AX40)) -> 27 | F40: =G40&J40 -> 34RIO AVE 200 SPE LTDA. | G40: =1+SUMPRODUCT(($J$2:$J$1437=$J40)*(AY$2:AY$1437>AY40)) -> 34 | H40: =I40&J40 -> 75RIO AVE 200 SPE LTDA. | I40: =1+SUMPRODUCT(($J$2:$J$1437=$J40)*(AZ$2:AZ$1437>AZ40)) -> 75 | J40: RIO AVE 200 SPE LTDA. | K40: ALISSON FERNANDES DA SILVA | L40: Armador de Estrutura de Concreto | M40: OBRA | N40: 1655.85 | O40: 2156 | P40: 45909 | R40: 2156 | AA40: 2.92 | AB40: 20.84 | AC40: 230.95714 | AD40: 140 | AE40: 745.28571 | AH40: 13.77 | AI40: 0 | AJ40: 646.46 | AK40: 145.15 | AR40: 33.79 | AS40: -924 | AW40: =AJ40+ROW(C40)/1000000 -> 646.46004 | AX40: =AD40+ROW(C40)/1000000 -> 140.00004 | AY40: =AB40+ROW(A40)/1000000 -> 20.84004 | AZ40: =AP40+ROW(A40)/1000000 -> 4e-05
...
